<?xml version="1.0" ?>
<!-- =================================================================================== -->
<!-- |    This document was autogenerated by xacro from kuka_kr4.xacro                 | -->
<!-- |    EDITING THIS FILE BY HAND IS NOT RECOMMENDED                                 | -->
<!-- =================================================================================== -->
<robot name="kuka_kr4">
  <material name="silver">
    <color rgba="0.700 0.700 0.700 1.000"/>
  </material>
  <transmission name="Revolucion1_tran">
    <type>transmission_interface/SimpleTransmission</type>
    <joint name="Revolucion1">
      <hardwareInterface>hardware_interface/EffortJointInterface</hardwareInterface>
    </joint>
    <actuator name="Revolucion1_actr">
      <hardwareInterface>hardware_interface/EffortJointInterface</hardwareInterface>
      <mechanicalReduction>1</mechanicalReduction>
    </actuator>
  </transmission>
  <transmission name="Revolucion2_tran">
    <type>transmission_interface/SimpleTransmission</type>
    <joint name="Revolucion2">
      <hardwareInterface>hardware_interface/EffortJointInterface</hardwareInterface>
    </joint>
    <actuator name="Revolucion2_actr">
      <hardwareInterface>hardware_interface/EffortJointInterface</hardwareInterface>
      <mechanicalReduction>1</mechanicalReduction>
    </actuator>
  </transmission>
  <transmission name="Revolucion3_tran">
    <type>transmission_interface/SimpleTransmission</type>
    <joint name="Revolucion3">
      <hardwareInterface>hardware_interface/EffortJointInterface</hardwareInterface>
    </joint>
    <actuator name="Revolucion3_actr">
      <hardwareInterface>hardware_interface/EffortJointInterface</hardwareInterface>
      <mechanicalReduction>1</mechanicalReduction>
    </actuator>
  </transmission>
  <transmission name="Revolucion4_tran">
    <type>transmission_interface/SimpleTransmission</type>
    <joint name="Revolucion4">
      <hardwareInterface>hardware_interface/EffortJointInterface</hardwareInterface>
    </joint>
    <actuator name="Revolucion4_actr">
      <hardwareInterface>hardware_interface/EffortJointInterface</hardwareInterface>
      <mechanicalReduction>1</mechanicalReduction>
    </actuator>
  </transmission>
  <transmission name="Revolucion5_tran">
    <type>transmission_interface/SimpleTransmission</type>
    <joint name="Revolucion5">
      <hardwareInterface>hardware_interface/EffortJointInterface</hardwareInterface>
    </joint>
    <actuator name="Revolucion5_actr">
      <hardwareInterface>hardware_interface/EffortJointInterface</hardwareInterface>
      <mechanicalReduction>1</mechanicalReduction>
    </actuator>
  </transmission>
  <transmission name="Revolucion6_tran">
    <type>transmission_interface/SimpleTransmission</type>
    <joint name="Revolucion6">
      <hardwareInterface>hardware_interface/EffortJointInterface</hardwareInterface>
    </joint>
    <actuator name="Revolucion6_actr">
      <hardwareInterface>hardware_interface/EffortJointInterface</hardwareInterface>
      <mechanicalReduction>1</mechanicalReduction>
    </actuator>
  </transmission>
  <gazebo>
    <plugin filename="libgazebo_ros_control.so" name="control"/>
  </gazebo>
  <gazebo reference="base_link">
    <material>Gazebo/Silver</material>
    <mu1>0.2</mu1>
    <mu2>0.2</mu2>
    <selfCollide>true</selfCollide>
    <gravity>true</gravity>
  </gazebo>
  <gazebo reference="arm_1_1">
    <material>Gazebo/Silver</material>
    <mu1>0.2</mu1>
    <mu2>0.2</mu2>
    <selfCollide>true</selfCollide>
  </gazebo>
  <gazebo reference="arm_2_1">
    <material>Gazebo/Silver</material>
    <mu1>0.2</mu1>
    <mu2>0.2</mu2>
    <selfCollide>true</selfCollide>
  </gazebo>
  <gazebo reference="arm_3_1">
    <material>Gazebo/Silver</material>
    <mu1>0.2</mu1>
    <mu2>0.2</mu2>
    <selfCollide>true</selfCollide>
  </gazebo>
  <gazebo reference="arm_4_1">
    <material>Gazebo/Silver</material>
    <mu1>0.2</mu1>
    <mu2>0.2</mu2>
    <selfCollide>true</selfCollide>
  </gazebo>
  <gazebo reference="arm_5_1">
    <material>Gazebo/Silver</material>
    <mu1>0.2</mu1>
    <mu2>0.2</mu2>
    <selfCollide>true</selfCollide>
  </gazebo>
  <gazebo reference="efector_final_1">
    <material>Gazebo/Silver</material>
    <mu1>0.2</mu1>
    <mu2>0.2</mu2>
    <selfCollide>true</selfCollide>
  </gazebo>
  <link name="base_link">
    <inertial>
      <origin rpy="0 0 0" xyz="-0.03685052519874798 0.0002444650496217044 0.09028031393493556"/>
      <mass value="52.09763807147974"/>
      <inertia ixx="0.237109" ixy="0.002106" ixz="0.003044" iyy="0.389106" iyz="0.000599" izz="0.374461"/>
    </inertial>
    <visual>
      <origin rpy="0 0 0" xyz="0 0 0"/>
      <geometry>
        <mesh filename="package://kuka_kr4_description/meshes/base_link.stl" scale="0.001 0.001 0.001"/>
      </geometry>
      <material name="silver"/>
    </visual>
    <collision>
      <origin rpy="0 0 0" xyz="0 0 0"/>
      <geometry>
        <mesh filename="package://kuka_kr4_description/meshes/base_link.stl" scale="0.001 0.001 0.001"/>
      </geometry>
    </collision>
  </link>
  <link name="arm_1_1">
    <inertial>
      <origin rpy="0 0 0" xyz="-0.003988136239754784 -0.0007020266635606675 0.08231492151934183"/>
      <mass value="27.389571489728127"/>
      <inertia ixx="0.228578" ixy="0.000127" ixz="-0.000588" iyy="0.147549" iyz="0.001416" izz="0.163411"/>
    </inertial>
    <visual>
      <origin rpy="0 0 0" xyz="0.0 0.0 -0.177"/>
      <geometry>
        <mesh filename="package://kuka_kr4_description/meshes/arm_1_1.stl" scale="0.001 0.001 0.001"/>
      </geometry>
      <material name="silver"/>
    </visual>
    <collision>
      <origin rpy="0 0 0" xyz="0.0 0.0 -0.177"/>
      <geometry>
        <mesh filename="package://kuka_kr4_description/meshes/arm_1_1.stl" scale="0.001 0.001 0.001"/>
      </geometry>
    </collision>
  </link>
  <link name="arm_2_1">
    <inertial>
      <origin rpy="0 0 0" xyz="-0.010662422573048202 -0.06312208973151316 0.11773443401249284"/>
      <mass value="37.16046001565583"/>
      <inertia ixx="0.491976" ixy="-2.1e-05" ixz="0.007959" iyy="0.430396" iyz="0.004479" izz="0.134175"/>
    </inertial>
    <visual>
      <origin rpy="0 0 0" xyz="0.0 -0.064 -0.3292"/>
      <geometry>
        <mesh filename="package://kuka_kr4_description/meshes/arm_2_1.stl" scale="0.001 0.001 0.001"/>
      </geometry>
      <material name="silver"/>
    </visual>
    <collision>
      <origin rpy="0 0 0" xyz="0.0 -0.064 -0.3292"/>
      <geometry>
        <mesh filename="package://kuka_kr4_description/meshes/arm_2_1.stl" scale="0.001 0.001 0.001"/>
      </geometry>
    </collision>
  </link>
  <link name="arm_3_1">
    <inertial>
      <origin rpy="0 0 0" xyz="0.05016463351790332 -0.06115462726961939 0.009515195828368905"/>
      <mass value="16.81095567354773"/>
      <inertia ixx="0.027845" ixy="0.000717" ixz="-0.008555" iyy="0.081909" iyz="0.000107" izz="0.078872"/>
    </inertial>
    <visual>
      <origin rpy="0 0 0" xyz="0.0 -0.062 -0.6192"/>
      <geometry>
        <mesh filename="package://kuka_kr4_description/meshes/arm_3_1.stl" scale="0.001 0.001 0.001"/>
      </geometry>
      <material name="silver"/>
    </visual>
    <collision>
      <origin rpy="0 0 0" xyz="0.0 -0.062 -0.6192"/>
      <geometry>
        <mesh filename="package://kuka_kr4_description/meshes/arm_3_1.stl" scale="0.001 0.001 0.001"/>
      </geometry>
    </collision>
  </link>
  <link name="arm_4_1">
    <inertial>
      <origin rpy="0 0 0" xyz="0.07072783604162342 0.002541906720189751 0.0014460342528421766"/>
      <mass value="8.604519243549056"/>
      <inertia ixx="0.018169" ixy="-0.002064" ixz="0.000211" iyy="0.020163" iyz="-0.000351" izz="0.028764"/>
    </inertial>
    <visual>
      <origin rpy="0 0 0" xyz="-0.1632 0.0 -0.6392"/>
      <geometry>
        <mesh filename="package://kuka_kr4_description/meshes/arm_4_1.stl" scale="0.001 0.001 0.001"/>
      </geometry>
      <material name="silver"/>
    </visual>
    <collision>
      <origin rpy="0 0 0" xyz="-0.1632 0.0 -0.6392"/>
      <geometry>
        <mesh filename="package://kuka_kr4_description/meshes/arm_4_1.stl" scale="0.001 0.001 0.001"/>
      </geometry>
    </collision>
  </link>
  <link name="arm_5_1">
    <inertial>
      <origin rpy="0 0 0" xyz="0.0031397968802750476 -0.04852169254529081 -1.247668779158495e-05"/>
      <mass value="4.272813571114689"/>
      <inertia ixx="0.003752" ixy="-4.2e-05" ixz="-1e-05" iyy="0.005073" iyz="1e-06" izz="0.005384"/>
    </inertial>
    <visual>
      <origin rpy="0 0 0" xyz="-0.31 -0.049 -0.6392"/>
      <geometry>
        <mesh filename="package://kuka_kr4_description/meshes/arm_5_1.stl" scale="0.001 0.001 0.001"/>
      </geometry>
      <material name="silver"/>
    </visual>
    <collision>
      <origin rpy="0 0 0" xyz="-0.31 -0.049 -0.6392"/>
      <geometry>
        <mesh filename="package://kuka_kr4_description/meshes/arm_5_1.stl" scale="0.001 0.001 0.001"/>
      </geometry>
    </collision>
  </link>
  <link name="efector_final_1">
    <inertial>
      <origin rpy="0 0 0" xyz="0.014533865884605035 -2.541966860416472e-06 -2.4161364704511357e-06"/>
      <mass value="0.26603789816689666"/>
      <inertia ixx="7.4e-05" ixy="0.0" ixz="0.0" iyy="4.8e-05" iyz="-0.0" izz="4.8e-05"/>
    </inertial>
    <visual>
      <origin rpy="0 0 0" xyz="-0.358 0.0 -0.6392"/>
      <geometry>
        <mesh filename="package://kuka_kr4_description/meshes/efector_final_1.stl" scale="0.001 0.001 0.001"/>
      </geometry>
      <material name="silver"/>
    </visual>
    <collision>
      <origin rpy="0 0 0" xyz="-0.358 0.0 -0.6392"/>
      <geometry>
        <mesh filename="package://kuka_kr4_description/meshes/efector_final_1.stl" scale="0.001 0.001 0.001"/>
      </geometry>
    </collision>
  </link>
  <joint name="Revolucion1" type="continuous">
    <origin rpy="0 0 0" xyz="0.0 0.0 0.177"/>
    <parent link="base_link"/>
    <child link="arm_1_1"/>
    <axis xyz="0.0 -0.0 1.0"/>
  </joint>
  <joint name="Revolucion2" type="continuous">
    <origin rpy="0 0 0" xyz="0.0 0.064 0.1522"/>
    <parent link="arm_1_1"/>
    <child link="arm_2_1"/>
    <axis xyz="-0.0 1.0 0.0"/>
  </joint>
  <joint name="Revolucion3" type="continuous">
    <origin rpy="0 0 0" xyz="0.0 -0.002 0.29"/>
    <parent link="arm_2_1"/>
    <child link="arm_3_1"/>
    <axis xyz="0.0 1.0 0.0"/>
  </joint>
  <joint name="Revolucion4" type="continuous">
    <origin rpy="0 0 0" xyz="0.1632 -0.062 0.02"/>
    <parent link="arm_3_1"/>
    <child link="arm_4_1"/>
    <axis xyz="-1.0 0.0 -0.0"/>
  </joint>
  <joint name="Revolucion5" type="continuous">
    <origin rpy="0 0 0" xyz="0.1468 0.049 0.0"/>
    <parent link="arm_4_1"/>
    <child link="arm_5_1"/>
    <axis xyz="0.0 1.0 0.0"/>
  </joint>
  <joint name="Revolucion6" type="continuous">
    <origin rpy="0 0 0" xyz="0.048 -0.049 0.0"/>
    <parent link="arm_5_1"/>
    <child link="efector_final_1"/>
    <axis xyz="-1.0 0.0 -0.0"/>
  </joint>

  
</robot>

